WARNING 2019-10-21 13:08:33,300 log 5956 5696 Not Found: /www.py9v5zj1h.bkt.clouddn.com/FspEtcW7aZ2O5_YsHdHsRcTXD3ML
WARNING 2019-10-21 13:08:40,310 log 5956 5696 Not Found: /www.py9v5zj1h.bkt.clouddn.com/FspEtcW7aZ2O5_YsHdHsRcTXD3ML
WARNING 2019-10-21 13:08:44,232 log 5956 5696 Not Found: /www.py9v5zj1h.bkt.clouddn.com/FspEtcW7aZ2O5_YsHdHsRcTXD3ML
ERROR 2019-10-21 15:31:49,352 log 548 9752 Internal Server Error: /article/article_updown/
Traceback (most recent call last):
  File "C:\envs\LoveAndShare\lib\site-packages\django\core\handlers\exception.py", line 34, in inner
    response = get_response(request)
  File "C:\envs\LoveAndShare\lib\site-packages\django\core\handlers\base.py", line 115, in _get_response
    response = self.process_exception_by_middleware(e, request)
  File "C:\envs\LoveAndShare\lib\site-packages\django\core\handlers\base.py", line 113, in _get_response
    response = wrapped_callback(request, *callback_args, **callback_kwargs)
  File "C:\Users\1843326800\PycharmProjects\LoveAndShare\apps\article\views.py", line 58, in article_updown
    logger.info("jjjj{'key'}".format(key="jjjjjjj"))
KeyError: "'key'"
ERROR 2019-10-21 15:31:56,051 log 548 9752 Internal Server Error: /article/article_updown/
Traceback (most recent call last):
  File "C:\envs\LoveAndShare\lib\site-packages\django\core\handlers\exception.py", line 34, in inner
    response = get_response(request)
  File "C:\envs\LoveAndShare\lib\site-packages\django\core\handlers\base.py", line 115, in _get_response
    response = self.process_exception_by_middleware(e, request)
  File "C:\envs\LoveAndShare\lib\site-packages\django\core\handlers\base.py", line 113, in _get_response
    response = wrapped_callback(request, *callback_args, **callback_kwargs)
  File "C:\Users\1843326800\PycharmProjects\LoveAndShare\apps\article\views.py", line 58, in article_updown
    logger.info("jjjj{'key'}".format(key="jjjjjjj"))
KeyError: "'key'"
ERROR 2019-10-21 15:31:57,380 log 548 9752 Internal Server Error: /article/article_updown/
Traceback (most recent call last):
  File "C:\envs\LoveAndShare\lib\site-packages\django\core\handlers\exception.py", line 34, in inner
    response = get_response(request)
  File "C:\envs\LoveAndShare\lib\site-packages\django\core\handlers\base.py", line 115, in _get_response
    response = self.process_exception_by_middleware(e, request)
  File "C:\envs\LoveAndShare\lib\site-packages\django\core\handlers\base.py", line 113, in _get_response
    response = wrapped_callback(request, *callback_args, **callback_kwargs)
  File "C:\Users\1843326800\PycharmProjects\LoveAndShare\apps\article\views.py", line 58, in article_updown
    logger.info("jjjj{'key'}".format(key="jjjjjjj"))
KeyError: "'key'"
ERROR 2019-10-21 15:31:57,614 log 548 9752 Internal Server Error: /article/article_updown/
Traceback (most recent call last):
  File "C:\envs\LoveAndShare\lib\site-packages\django\core\handlers\exception.py", line 34, in inner
    response = get_response(request)
  File "C:\envs\LoveAndShare\lib\site-packages\django\core\handlers\base.py", line 115, in _get_response
    response = self.process_exception_by_middleware(e, request)
  File "C:\envs\LoveAndShare\lib\site-packages\django\core\handlers\base.py", line 113, in _get_response
    response = wrapped_callback(request, *callback_args, **callback_kwargs)
  File "C:\Users\1843326800\PycharmProjects\LoveAndShare\apps\article\views.py", line 58, in article_updown
    logger.info("jjjj{'key'}".format(key="jjjjjjj"))
KeyError: "'key'"
ERROR 2019-10-21 15:31:59,125 log 548 9752 Internal Server Error: /article/article_updown/
Traceback (most recent call last):
  File "C:\envs\LoveAndShare\lib\site-packages\django\core\handlers\exception.py", line 34, in inner
    response = get_response(request)
  File "C:\envs\LoveAndShare\lib\site-packages\django\core\handlers\base.py", line 115, in _get_response
    response = self.process_exception_by_middleware(e, request)
  File "C:\envs\LoveAndShare\lib\site-packages\django\core\handlers\base.py", line 113, in _get_response
    response = wrapped_callback(request, *callback_args, **callback_kwargs)
  File "C:\Users\1843326800\PycharmProjects\LoveAndShare\apps\article\views.py", line 58, in article_updown
    logger.info("jjjj{'key'}".format(key="jjjjjjj"))
KeyError: "'key'"
ERROR 2019-10-21 15:32:03,739 log 548 9752 Internal Server Error: /article/article_updown/
Traceback (most recent call last):
  File "C:\envs\LoveAndShare\lib\site-packages\django\core\handlers\exception.py", line 34, in inner
    response = get_response(request)
  File "C:\envs\LoveAndShare\lib\site-packages\django\core\handlers\base.py", line 115, in _get_response
    response = self.process_exception_by_middleware(e, request)
  File "C:\envs\LoveAndShare\lib\site-packages\django\core\handlers\base.py", line 113, in _get_response
    response = wrapped_callback(request, *callback_args, **callback_kwargs)
  File "C:\Users\1843326800\PycharmProjects\LoveAndShare\apps\article\views.py", line 58, in article_updown
    logger.info("jjjj{'key'}".format(key="jjjjjjj"))
KeyError: "'key'"
ERROR 2019-10-21 15:32:04,654 log 548 9752 Internal Server Error: /article/article_updown/
Traceback (most recent call last):
  File "C:\envs\LoveAndShare\lib\site-packages\django\core\handlers\exception.py", line 34, in inner
    response = get_response(request)
  File "C:\envs\LoveAndShare\lib\site-packages\django\core\handlers\base.py", line 115, in _get_response
    response = self.process_exception_by_middleware(e, request)
  File "C:\envs\LoveAndShare\lib\site-packages\django\core\handlers\base.py", line 113, in _get_response
    response = wrapped_callback(request, *callback_args, **callback_kwargs)
  File "C:\Users\1843326800\PycharmProjects\LoveAndShare\apps\article\views.py", line 58, in article_updown
    logger.info("jjjj{'key'}".format(key="jjjjjjj"))
KeyError: "'key'"
ERROR 2019-10-21 15:32:05,156 log 548 9752 Internal Server Error: /article/article_updown/
Traceback (most recent call last):
  File "C:\envs\LoveAndShare\lib\site-packages\django\core\handlers\exception.py", line 34, in inner
    response = get_response(request)
  File "C:\envs\LoveAndShare\lib\site-packages\django\core\handlers\base.py", line 115, in _get_response
    response = self.process_exception_by_middleware(e, request)
  File "C:\envs\LoveAndShare\lib\site-packages\django\core\handlers\base.py", line 113, in _get_response
    response = wrapped_callback(request, *callback_args, **callback_kwargs)
  File "C:\Users\1843326800\PycharmProjects\LoveAndShare\apps\article\views.py", line 58, in article_updown
    logger.info("jjjj{'key'}".format(key="jjjjjjj"))
KeyError: "'key'"
ERROR 2019-10-21 15:32:07,516 log 548 9752 Internal Server Error: /article/article_updown/
Traceback (most recent call last):
  File "C:\envs\LoveAndShare\lib\site-packages\django\core\handlers\exception.py", line 34, in inner
    response = get_response(request)
  File "C:\envs\LoveAndShare\lib\site-packages\django\core\handlers\base.py", line 115, in _get_response
    response = self.process_exception_by_middleware(e, request)
  File "C:\envs\LoveAndShare\lib\site-packages\django\core\handlers\base.py", line 113, in _get_response
    response = wrapped_callback(request, *callback_args, **callback_kwargs)
  File "C:\Users\1843326800\PycharmProjects\LoveAndShare\apps\article\views.py", line 58, in article_updown
    logger.info("jjjj{'key'}".format(key="jjjjjjj"))
KeyError: "'key'"
ERROR 2019-10-21 15:32:13,600 log 548 9752 Internal Server Error: /article/article_updown/
Traceback (most recent call last):
  File "C:\envs\LoveAndShare\lib\site-packages\django\core\handlers\exception.py", line 34, in inner
    response = get_response(request)
  File "C:\envs\LoveAndShare\lib\site-packages\django\core\handlers\base.py", line 115, in _get_response
    response = self.process_exception_by_middleware(e, request)
  File "C:\envs\LoveAndShare\lib\site-packages\django\core\handlers\base.py", line 113, in _get_response
    response = wrapped_callback(request, *callback_args, **callback_kwargs)
  File "C:\Users\1843326800\PycharmProjects\LoveAndShare\apps\article\views.py", line 58, in article_updown
    logger.info("jjjj{'key'}".format(key="jjjjjjj"))
KeyError: "'key'"
ERROR 2019-10-21 15:32:14,454 log 548 9752 Internal Server Error: /article/article_updown/
Traceback (most recent call last):
  File "C:\envs\LoveAndShare\lib\site-packages\django\core\handlers\exception.py", line 34, in inner
    response = get_response(request)
  File "C:\envs\LoveAndShare\lib\site-packages\django\core\handlers\base.py", line 115, in _get_response
    response = self.process_exception_by_middleware(e, request)
  File "C:\envs\LoveAndShare\lib\site-packages\django\core\handlers\base.py", line 113, in _get_response
    response = wrapped_callback(request, *callback_args, **callback_kwargs)
  File "C:\Users\1843326800\PycharmProjects\LoveAndShare\apps\article\views.py", line 58, in article_updown
    logger.info("jjjj{'key'}".format(key="jjjjjjj"))
KeyError: "'key'"
WARNING 2019-10-21 15:32:19,693 log 548 9752 Not Found: /article/article_editor/6//www.py9v5zj1h.bkt.clouddn.com/FjGOpuMPmJ4H3nOtQp5m7GhAM7Jy
WARNING 2019-10-21 15:32:19,717 log 548 6256 Not Found: /article/article_editor/6/py9v5zj1h.bkt.clouddn.com/FjGOpuMPmJ4H3nOtQp5m7GhAM7Jy
WARNING 2019-10-21 15:32:19,725 log 548 13184 Not Found: /article/article_editor/6/py9v5zj1h.bkt.clouddn.com/FpqlKEIu-p67PmBpKw8ZbS644tFo
ERROR 2019-10-21 15:32:21,855 log 548 13184 Internal Server Error: /article/article_updown/
Traceback (most recent call last):
  File "C:\envs\LoveAndShare\lib\site-packages\django\core\handlers\exception.py", line 34, in inner
    response = get_response(request)
  File "C:\envs\LoveAndShare\lib\site-packages\django\core\handlers\base.py", line 115, in _get_response
    response = self.process_exception_by_middleware(e, request)
  File "C:\envs\LoveAndShare\lib\site-packages\django\core\handlers\base.py", line 113, in _get_response
    response = wrapped_callback(request, *callback_args, **callback_kwargs)
  File "C:\Users\1843326800\PycharmProjects\LoveAndShare\apps\article\views.py", line 58, in article_updown
    logger.info("jjjj{'key'}".format(key="jjjjjjj"))
KeyError: "'key'"
ERROR 2019-10-21 15:32:25,293 log 548 13184 Internal Server Error: /article/article_updown/
Traceback (most recent call last):
  File "C:\envs\LoveAndShare\lib\site-packages\django\core\handlers\exception.py", line 34, in inner
    response = get_response(request)
  File "C:\envs\LoveAndShare\lib\site-packages\django\core\handlers\base.py", line 115, in _get_response
    response = self.process_exception_by_middleware(e, request)
  File "C:\envs\LoveAndShare\lib\site-packages\django\core\handlers\base.py", line 113, in _get_response
    response = wrapped_callback(request, *callback_args, **callback_kwargs)
  File "C:\Users\1843326800\PycharmProjects\LoveAndShare\apps\article\views.py", line 58, in article_updown
    logger.info("jjjj{'key'}".format(key="jjjjjjj"))
KeyError: "'key'"
ERROR 2019-10-21 15:32:26,024 log 548 13184 Internal Server Error: /article/article_updown/
Traceback (most recent call last):
  File "C:\envs\LoveAndShare\lib\site-packages\django\core\handlers\exception.py", line 34, in inner
    response = get_response(request)
  File "C:\envs\LoveAndShare\lib\site-packages\django\core\handlers\base.py", line 115, in _get_response
    response = self.process_exception_by_middleware(e, request)
  File "C:\envs\LoveAndShare\lib\site-packages\django\core\handlers\base.py", line 113, in _get_response
    response = wrapped_callback(request, *callback_args, **callback_kwargs)
  File "C:\Users\1843326800\PycharmProjects\LoveAndShare\apps\article\views.py", line 58, in article_updown
    logger.info("jjjj{'key'}".format(key="jjjjjjj"))
KeyError: "'key'"
ERROR 2019-10-21 15:32:27,056 log 548 13184 Internal Server Error: /article/article_updown/
Traceback (most recent call last):
  File "C:\envs\LoveAndShare\lib\site-packages\django\core\handlers\exception.py", line 34, in inner
    response = get_response(request)
  File "C:\envs\LoveAndShare\lib\site-packages\django\core\handlers\base.py", line 115, in _get_response
    response = self.process_exception_by_middleware(e, request)
  File "C:\envs\LoveAndShare\lib\site-packages\django\core\handlers\base.py", line 113, in _get_response
    response = wrapped_callback(request, *callback_args, **callback_kwargs)
  File "C:\Users\1843326800\PycharmProjects\LoveAndShare\apps\article\views.py", line 58, in article_updown
    logger.info("jjjj{'key'}".format(key="jjjjjjj"))
KeyError: "'key'"
ERROR 2019-10-21 15:32:27,886 log 548 13184 Internal Server Error: /article/article_updown/
Traceback (most recent call last):
  File "C:\envs\LoveAndShare\lib\site-packages\django\core\handlers\exception.py", line 34, in inner
    response = get_response(request)
  File "C:\envs\LoveAndShare\lib\site-packages\django\core\handlers\base.py", line 115, in _get_response
    response = self.process_exception_by_middleware(e, request)
  File "C:\envs\LoveAndShare\lib\site-packages\django\core\handlers\base.py", line 113, in _get_response
    response = wrapped_callback(request, *callback_args, **callback_kwargs)
  File "C:\Users\1843326800\PycharmProjects\LoveAndShare\apps\article\views.py", line 58, in article_updown
    logger.info("jjjj{'key'}".format(key="jjjjjjj"))
KeyError: "'key'"
ERROR 2019-10-21 15:32:28,658 log 548 13184 Internal Server Error: /article/article_updown/
Traceback (most recent call last):
  File "C:\envs\LoveAndShare\lib\site-packages\django\core\handlers\exception.py", line 34, in inner
    response = get_response(request)
  File "C:\envs\LoveAndShare\lib\site-packages\django\core\handlers\base.py", line 115, in _get_response
    response = self.process_exception_by_middleware(e, request)
  File "C:\envs\LoveAndShare\lib\site-packages\django\core\handlers\base.py", line 113, in _get_response
    response = wrapped_callback(request, *callback_args, **callback_kwargs)
  File "C:\Users\1843326800\PycharmProjects\LoveAndShare\apps\article\views.py", line 58, in article_updown
    logger.info("jjjj{'key'}".format(key="jjjjjjj"))
KeyError: "'key'"
ERROR 2019-10-21 15:32:29,369 log 548 13184 Internal Server Error: /article/article_updown/
Traceback (most recent call last):
  File "C:\envs\LoveAndShare\lib\site-packages\django\core\handlers\exception.py", line 34, in inner
    response = get_response(request)
  File "C:\envs\LoveAndShare\lib\site-packages\django\core\handlers\base.py", line 115, in _get_response
    response = self.process_exception_by_middleware(e, request)
  File "C:\envs\LoveAndShare\lib\site-packages\django\core\handlers\base.py", line 113, in _get_response
    response = wrapped_callback(request, *callback_args, **callback_kwargs)
  File "C:\Users\1843326800\PycharmProjects\LoveAndShare\apps\article\views.py", line 58, in article_updown
    logger.info("jjjj{'key'}".format(key="jjjjjjj"))
KeyError: "'key'"
WARNING 2019-10-21 15:32:30,624 log 548 13184 Not Found: /article/article_editor/6//www.py9v5zj1h.bkt.clouddn.com/FjGOpuMPmJ4H3nOtQp5m7GhAM7Jy
WARNING 2019-10-21 15:32:30,639 log 548 6256 Not Found: /article/article_editor/6/py9v5zj1h.bkt.clouddn.com/FjGOpuMPmJ4H3nOtQp5m7GhAM7Jy
WARNING 2019-10-21 15:32:30,650 log 548 9752 Not Found: /article/article_editor/6/py9v5zj1h.bkt.clouddn.com/FpqlKEIu-p67PmBpKw8ZbS644tFo
ERROR 2019-10-21 15:32:32,468 log 548 9752 Internal Server Error: /article/article_updown/
Traceback (most recent call last):
  File "C:\envs\LoveAndShare\lib\site-packages\django\core\handlers\exception.py", line 34, in inner
    response = get_response(request)
  File "C:\envs\LoveAndShare\lib\site-packages\django\core\handlers\base.py", line 115, in _get_response
    response = self.process_exception_by_middleware(e, request)
  File "C:\envs\LoveAndShare\lib\site-packages\django\core\handlers\base.py", line 113, in _get_response
    response = wrapped_callback(request, *callback_args, **callback_kwargs)
  File "C:\Users\1843326800\PycharmProjects\LoveAndShare\apps\article\views.py", line 58, in article_updown
    logger.info("jjjj{'key'}".format(key="jjjjjjj"))
KeyError: "'key'"
ERROR 2019-10-21 15:32:33,499 log 548 9752 Internal Server Error: /article/article_updown/
Traceback (most recent call last):
  File "C:\envs\LoveAndShare\lib\site-packages\django\core\handlers\exception.py", line 34, in inner
    response = get_response(request)
  File "C:\envs\LoveAndShare\lib\site-packages\django\core\handlers\base.py", line 115, in _get_response
    response = self.process_exception_by_middleware(e, request)
  File "C:\envs\LoveAndShare\lib\site-packages\django\core\handlers\base.py", line 113, in _get_response
    response = wrapped_callback(request, *callback_args, **callback_kwargs)
  File "C:\Users\1843326800\PycharmProjects\LoveAndShare\apps\article\views.py", line 58, in article_updown
    logger.info("jjjj{'key'}".format(key="jjjjjjj"))
KeyError: "'key'"
WARNING 2019-10-21 15:32:43,783 log 548 9752 Not Found: /article/article_editor/6//www.py9v5zj1h.bkt.clouddn.com/FjGOpuMPmJ4H3nOtQp5m7GhAM7Jy
WARNING 2019-10-21 15:32:43,798 log 548 6256 Not Found: /article/article_editor/6/py9v5zj1h.bkt.clouddn.com/FjGOpuMPmJ4H3nOtQp5m7GhAM7Jy
WARNING 2019-10-21 15:32:53,915 log 10424 8984 Not Found: /article/article_editor/6/py9v5zj1h.bkt.clouddn.com/FjGOpuMPmJ4H3nOtQp5m7GhAM7Jy
WARNING 2019-10-21 15:32:53,922 log 10424 6956 Not Found: /article/article_editor/6//www.py9v5zj1h.bkt.clouddn.com/FjGOpuMPmJ4H3nOtQp5m7GhAM7Jy
WARNING 2019-10-21 15:32:53,948 log 10424 400 Not Found: /article/article_editor/6/py9v5zj1h.bkt.clouddn.com/FpqlKEIu-p67PmBpKw8ZbS644tFo
ERROR 2019-10-21 15:33:22,454 log 5296 3396 Internal Server Error: /article/article_detail/9/
Traceback (most recent call last):
  File "C:\envs\LoveAndShare\lib\site-packages\django\core\handlers\exception.py", line 34, in inner
    response = get_response(request)
  File "C:\envs\LoveAndShare\lib\site-packages\django\core\handlers\base.py", line 115, in _get_response
    response = self.process_exception_by_middleware(e, request)
  File "C:\envs\LoveAndShare\lib\site-packages\django\core\handlers\base.py", line 113, in _get_response
    response = wrapped_callback(request, *callback_args, **callback_kwargs)
  File "C:\Users\1843326800\PycharmProjects\LoveAndShare\apps\article\views.py", line 27, in article_detail
    logger.info("jjjj{'key'}".format(key="jjjjjjj"))
KeyError: "'key'"
ERROR 2019-10-21 15:33:31,552 log 5296 3396 Internal Server Error: /article/article_detail/9/
Traceback (most recent call last):
  File "C:\envs\LoveAndShare\lib\site-packages\django\core\handlers\exception.py", line 34, in inner
    response = get_response(request)
  File "C:\envs\LoveAndShare\lib\site-packages\django\core\handlers\base.py", line 115, in _get_response
    response = self.process_exception_by_middleware(e, request)
  File "C:\envs\LoveAndShare\lib\site-packages\django\core\handlers\base.py", line 113, in _get_response
    response = wrapped_callback(request, *callback_args, **callback_kwargs)
  File "C:\Users\1843326800\PycharmProjects\LoveAndShare\apps\article\views.py", line 27, in article_detail
    logger.info("jjjj{'key'}".format(key="jjjjjjj"))
KeyError: "'key'"
ERROR 2019-10-21 15:33:56,864 log 5296 3396 Internal Server Error: /article/article_detail/9/
Traceback (most recent call last):
  File "C:\envs\LoveAndShare\lib\site-packages\django\core\handlers\exception.py", line 34, in inner
    response = get_response(request)
  File "C:\envs\LoveAndShare\lib\site-packages\django\core\handlers\base.py", line 115, in _get_response
    response = self.process_exception_by_middleware(e, request)
  File "C:\envs\LoveAndShare\lib\site-packages\django\core\handlers\base.py", line 113, in _get_response
    response = wrapped_callback(request, *callback_args, **callback_kwargs)
  File "C:\Users\1843326800\PycharmProjects\LoveAndShare\apps\article\views.py", line 27, in article_detail
    logger.info("jjjj{key}".format(key="jjjjjjj"))
KeyError: "'key'"
WARNING 2019-10-21 15:34:07,103 log 13068 8796 Not Found: /www.py9v5zj1h.bkt.clouddn.com/FspEtcW7aZ2O5_YsHdHsRcTXD3ML
WARNING 2019-10-21 15:34:13,752 log 13068 8796 Not Found: /www.py9v5zj1h.bkt.clouddn.com/FspEtcW7aZ2O5_YsHdHsRcTXD3ML
WARNING 2019-10-21 15:34:37,102 log 13068 8796 Not Found: /www.py9v5zj1h.bkt.clouddn.com/FspEtcW7aZ2O5_YsHdHsRcTXD3ML
WARNING 2019-10-21 15:35:58,014 views 872 8496 jjjjjjjjjjj
WARNING 2019-10-21 15:35:58,279 log 872 8496 Not Found: /www.py9v5zj1h.bkt.clouddn.com/FspEtcW7aZ2O5_YsHdHsRcTXD3ML
WARNING 2019-10-21 15:36:08,789 views 872 8496 jjjjjjjjjjj
WARNING 2019-10-21 15:36:08,889 log 872 8496 Not Found: /article/article_editor/6//www.py9v5zj1h.bkt.clouddn.com/FjGOpuMPmJ4H3nOtQp5m7GhAM7Jy
WARNING 2019-10-21 15:36:08,946 log 872 8496 Not Found: /article/article_editor/6/py9v5zj1h.bkt.clouddn.com/FjGOpuMPmJ4H3nOtQp5m7GhAM7Jy
WARNING 2019-10-21 15:36:08,959 log 872 12636 Not Found: /article/article_editor/6/py9v5zj1h.bkt.clouddn.com/FpqlKEIu-p67PmBpKw8ZbS644tFo
WARNING 2019-10-21 15:37:08,258 log 1080 6464 Not Found: /article/article_editor/6//www.py9v5zj1h.bkt.clouddn.com/FjGOpuMPmJ4H3nOtQp5m7GhAM7Jy
WARNING 2019-10-21 15:37:08,267 log 1080 8108 Not Found: /article/article_editor/6/py9v5zj1h.bkt.clouddn.com/FjGOpuMPmJ4H3nOtQp5m7GhAM7Jy
WARNING 2019-10-21 15:37:08,304 log 1080 7768 Not Found: /article/article_editor/6/py9v5zj1h.bkt.clouddn.com/FpqlKEIu-p67PmBpKw8ZbS644tFo
WARNING 2019-10-21 15:37:15,285 log 1080 8108 Not Found: /article/article_editor/6/py9v5zj1h.bkt.clouddn.com/FjGOpuMPmJ4H3nOtQp5m7GhAM7Jy
WARNING 2019-10-21 15:37:15,297 log 1080 7768 Not Found: /article/article_editor/6//www.py9v5zj1h.bkt.clouddn.com/FjGOpuMPmJ4H3nOtQp5m7GhAM7Jy
WARNING 2019-10-21 15:37:15,310 log 1080 6464 Not Found: /article/article_editor/6/py9v5zj1h.bkt.clouddn.com/FpqlKEIu-p67PmBpKw8ZbS644tFo
